Workbook
Name T: Loads!$C$63
Name TA: Loads!$C$49
Name TB: Loads!$C$50
Name TC: Loads!$C$51
Name TD: Loads!$C$52

Sheet Loads
B2: General Building Geometry
B3: Building Width | C3: 21 | D3: m
B4: Building Depth | C4: 24 | D4: m
B5: Beam Trib width | C5: 1.5 | D5: m | E5: <-- tributary width for beam UDL for gravity loads
B6: Frame Trib width | C6: 3 | D6: m | E6: <-- tributary width for gravity loads
B7: Lateral Trib width | C7: 6 | D7: m | E7: <-- tributary width for seismic mass / lateral loads
B8: No. Storeys | C8: =COUNT(C24:C32) -> 3
B10: g | C10: =9.81 -> 9.81 | D10: m/s²
B12: Partial Safety Factors and Combination Factors
C13: G | D13: Q | E13: W | F13: S | G13: I
B14: γ | C14: 1.35 | D14: 1.5 | E14: 1.5 | F14: 1.5
B15: ψ0 | D15: 0.7 | E15: 0.6 | F15: 0.5
B16: ψ1 | D16: 0.5 | E16: 0.2 | F16: 0.2
B17: ψ2 | D17: 0.3 | E17: 0 | F17: 0
B18: φ | D18: 1
B19: ψE | D19: =D18*D17 -> 0.3
B21: Floor Loads | S21: Snow Loads --> EC1-3:2010
I22: Floor Loads [kPa] | N22: Beam UDLs [kN/m]
B23: Storey | C23: G [kPa] | D23: Q [kPa] | E23: S [kPa] | F23: hi [m] | G23: Hi [m] | I23: LC1 - GQWSI | J23: LC2 - GQWSI | K23: LC3 - GQWSI | L23: LC4 - GQEI | N23: GQWSI | O23: GWQSI | P23: GSQWI | Q23: GQEI | S23: Ground snow load | T23: sk | U23: 0.85 | V23: kPa
B24: 1 | C24: 7.5 | D24: 3 | E24: =IF(C24<>"", IF(G24=MAX($G$24:$G$32), $U$29, 0), "") -> 0 | F24: 3.5 | G24: =IF(C24<>"", SUM($F$24:F24), "") -> 3.5 | I24: =IF(C24<>"", $C$14*C24+$D$14*D24+$F$14*$F$15*E24, "") -> 14.625 | J24: =IF(C24<>"", $C$14*C24 + $D$14*$D$15*D24 + $F$14*$F$15*E24, "") -> 13.275 | K24: =IF(C24<>"", $C$14*C24 + $D$14*$D$15*D24 + $F$14*E24, "") -> 13.275 | L24: =IF(C24<>"", C24+$D$19*D24, "") -> 8.4 | N24: =IF(C24<>"", I24*$C$5, "") -> 21.9375 | O24: =IF(C24<>"", J24*$C$5, "") -> 19.9125 | P24: =IF(C24<>"", K24*$C$5, "") -> 19.9125 | Q24: =IF(C24<>"", L24*$C$5, "") -> 12.6 | S24: Roof slope | T24: α | U24: 4 | V24: °
B25: 2 | C25: 7.5 | D25: 3 | E25: =IF(C25<>"", IF(G25=MAX($G$24:$G$32), $U$29, 0), "") -> 0 | F25: 3.5 | G25: =IF(C25<>"", SUM($F$24:F25), "") -> 7 | I25: =IF(C25<>"", $C$14*C25+$D$14*D25+$F$14*$F$15*E25, "") -> 14.625 | J25: =IF(C25<>"", $C$14*C25 + $D$14*$D$15*D25 + $F$14*$F$15*E25, "") -> 13.275 | K25: =IF(C25<>"", $C$14*C25 + $D$14*$D$15*D25 + $F$14*E25, "") -> 13.275 | L25: =IF(C25<>"", C25+$D$19*D25, "") -> 8.4 | N25: =IF(C25<>"", I25*$C$5, "") -> 21.9375 | O25: =IF(C25<>"", J25*$C$5, "") -> 19.9125 | P25: =IF(C25<>"", K25*$C$5, "") -> 19.9125 | Q25: =IF(C25<>"", L25*$C$5, "") -> 12.6 | T25: Ce | U25: 1
B26: 3 | C26: 7.5 | D26: 0 | E26: =IF(C26<>"", IF(G26=MAX($G$24:$G$32), $U$29, 0), "") -> 0.68 | F26: 3.5 | G26: =IF(C26<>"", SUM($F$24:F26), "") -> 10.5 | I26: =IF(C26<>"", $C$14*C26+$D$14*D26+$F$14*$F$15*E26, "") -> 10.635 | J26: =IF(C26<>"", $C$14*C26 + $D$14*$D$15*D26 + $F$14*$F$15*E26, "") -> 10.635 | K26: =IF(C26<>"", $C$14*C26 + $D$14*$D$15*D26 + $F$14*E26, "") -> 11.145 | L26: =IF(C26<>"", C26+$D$19*D26, "") -> 7.5 | N26: =IF(C26<>"", I26*$C$5, "") -> 15.9525 | O26: =IF(C26<>"", J26*$C$5, "") -> 15.9525 | P26: =IF(C26<>"", K26*$C$5, "") -> 16.7175 | Q26: =IF(C26<>"", L26*$C$5, "") -> 11.25 | T26: Ct | U26: 1
B27: 4 | E27: =IF(C27<>"", IF(G27=MAX($G$24:$G$32), $U$29, 0), "") | G27: =IF(C27<>"", SUM($F$24:F27), "") | I27: =IF(C27<>"", $C$14*C27+$D$14*D27+$F$14*$F$15*E27, "") | J27: =IF(C27<>"", $C$14*C27 + $D$14*$D$15*D27 + $F$14*$F$15*E27, "") | K27: =IF(C27<>"", $C$14*C27 + $D$14*$D$15*D27 + $F$14*E27, "") | L27: =IF(C27<>"", C27+$D$19*D27, "") | N27: =IF(C27<>"", I27*$C$5, "") | O27: =IF(C27<>"", J27*$C$5, "") | P27: =IF(C27<>"", K27*$C$5, "") | Q27: =IF(C27<>"", L27*$C$5, "")
B28: 5 | E28: =IF(C28<>"", IF(G28=MAX($G$24:$G$32), $U$29, 0), "") | G28: =IF(C28<>"", SUM($F$24:F28), "") | I28: =IF(C28<>"", $C$14*C28+$D$14*D28+$F$14*$F$15*E28, "") | J28: =IF(C28<>"", $C$14*C28 + $D$14*$D$15*D28 + $F$14*$F$15*E28, "") | K28: =IF(C28<>"", $C$14*C28 + $D$14*$D$15*D28 + $F$14*E28, "") | L28: =IF(C28<>"", C28+$D$19*D28, "") | N28: =IF(C28<>"", I28*$C$5, "") | O28: =IF(C28<>"", J28*$C$5, "") | P28: =IF(C28<>"", K28*$C$5, "") | Q28: =IF(C28<>"", L28*$C$5, "") | S28: Shape factor | T28: μ1 | U28: =IF(U24<30, 0.8, IF(U24<60, 0.8*(60-U24)/30, 0)) -> 0.8 | V28: kPa
B29: 6 | E29: =IF(C29<>"", IF(G29=MAX($G$24:$G$32), $U$29, 0), "") | G29: =IF(C29<>"", SUM($F$24:F29), "") | I29: =IF(C29<>"", $C$14*C29+$D$14*D29+$F$14*$F$15*E29, "") | J29: =IF(C29<>"", $C$14*C29 + $D$14*$D$15*D29 + $F$14*$F$15*E29, "") | K29: =IF(C29<>"", $C$14*C29 + $D$14*$D$15*D29 + $F$14*E29, "") | L29: =IF(C29<>"", C29+$D$19*D29, "") | N29: =IF(C29<>"", I29*$C$5, "") | O29: =IF(C29<>"", J29*$C$5, "") | P29: =IF(C29<>"", K29*$C$5, "") | Q29: =IF(C29<>"", L29*$C$5, "") | S29: Roof snow load | T29: s | U29: =U28*U25*U26*U23 -> 0.68 | V29: kPa
B30: 7 | E30: =IF(C30<>"", IF(G30=MAX($G$24:$G$32), $U$29, 0), "") | G30: =IF(C30<>"", SUM($F$24:F30), "") | I30: =IF(C30<>"", $C$14*C30+$D$14*D30+$F$14*$F$15*E30, "") | J30: =IF(C30<>"", $C$14*C30 + $D$14*$D$15*D30 + $F$14*$F$15*E30, "") | K30: =IF(C30<>"", $C$14*C30 + $D$14*$D$15*D30 + $F$14*E30, "") | L30: =IF(C30<>"", C30+$D$19*D30, "") | N30: =IF(C30<>"", I30*$C$5, "") | O30: =IF(C30<>"", J30*$C$5, "") | P30: =IF(C30<>"", K30*$C$5, "") | Q30: =IF(C30<>"", L30*$C$5, "")
B31: 8 | E31: =IF(C31<>"", IF(G31=MAX($G$24:$G$32), $U$29, 0), "") | G31: =IF(C31<>"", SUM($F$24:F31), "") | I31: =IF(C31<>"", $C$14*C31+$D$14*D31+$F$14*$F$15*E31, "") | J31: =IF(C31<>"", $C$14*C31 + $D$14*$D$15*D31 + $F$14*$F$15*E31, "") | K31: =IF(C31<>"", $C$14*C31 + $D$14*$D$15*D31 + $F$14*E31, "") | L31: =IF(C31<>"", C31+$D$19*D31, "") | N31: =IF(C31<>"", I31*$C$5, "") | O31: =IF(C31<>"", J31*$C$5, "") | P31: =IF(C31<>"", K31*$C$5, "") | Q31: =IF(C31<>"", L31*$C$5, "")
B32: 9 | E32: =IF(C32<>"", IF(G32=MAX($G$24:$G$32), $U$29, 0), "") | G32: =IF(C32<>"", SUM($F$24:F32), "") | I32: =IF(C32<>"", $C$14*C32+$D$14*D32+$F$14*$F$15*E32, "") | J32: =IF(C32<>"", $C$14*C32 + $D$14*$D$15*D32 + $F$14*$F$15*E32, "") | K32: =IF(C32<>"", $C$14*C32 + $D$14*$D$15*D32 + $F$14*E32, "") | L32: =IF(C32<>"", C32+$D$19*D32, "") | N32: =IF(C32<>"", I32*$C$5, "") | O32: =IF(C32<>"", J32*$C$5, "") | P32: =IF(C32<>"", K32*$C$5, "") | Q32: =IF(C32<>"", L32*$C$5, "")
B36: Seismic Loads --> EC8-1-1:2022 | L36: Wind Loads --> EC1-4:2010
B37: S_alpha_475 | C37: 0 | D37: g | L37: ρ | M37: 1.25 | N37: kg/m³ | Q37: k_r | R37: =0.19*(M44/0.05)^0.07 -> 0.23432882
B38: S_beta_475 | C38: =0.3*C37 -> 0 | D38: g | L38: Windzone | M38: 2 | Q38: v_b | R38: =M39*M41*M42 -> 25 | S38: m/s
B39: Soil Class | C39: C | E39: Storey | F39: W_i [kN] | G39: m_i [t] | I39: mi * Hi | J39: F_i [kN] | L39: v_b0 | M39: 25 | N39: m/s | Q39: h | R39: =SUM(F24:F32) -> 10.5 | S39: m | T39: <-- check this is the correct height
B40: FT | C40: 1 | E40: 1 | F40: =IF(C24<>"", L24*$C$3*$C$7, "") -> 1058.4 | G40: =IF(C24<>"", F40/$C$10, "") -> 107.88991 | I40: =IF(C24<>"", G40*G24, "") -> 377.61468 | J40: =IF(C24<>"", $C$70 * I40/$I$49, "") -> 0 | L40: q_b0 | M40: 0.39 | N40: m/s | Q40: d | R40: =C3 -> 21 | S40: m
B41: F_alpha | C41: =1.6*(1-0.2*C37) -> 1.6 | E41: 2 | F41: =IF(C25<>"", L25*$C$3*$C$7, "") -> 1058.4 | G41: =IF(C25<>"", F41/$C$10, "") -> 107.88991 | I41: =IF(C25<>"", G41*G25, "") -> 755.22936 | J41: =IF(C25<>"", $C$70 * I41/$I$49, "") -> 0 | L41: c_dir | M41: 1 | Q41: b | R41: =C4 -> 24 | S41: m
B42: F_beta | C42: =2.3*(1-0.3*C38) -> 2.3 | E42: 3 | F42: =IF(C26<>"", L26*$C$3*$C$7, "") -> 945 | G42: =IF(C26<>"", F42/$C$10, "") -> 96.330275 | I42: =IF(C26<>"", G42*G26, "") -> 1011.4679 | J42: =IF(C26<>"", $C$70 * I42/$I$49, "") -> 0 | L42: c_season | M42: 1 | Q42: h/d | R42: =R39/R40 -> 0.5
E43: 4 | F43: =IF(C27<>"", L27*$C$3*$C$7, "") | G43: =IF(C27<>"", F43/$C$10, "") | I43: =IF(C27<>"", G43*G27, "") | J43: =IF(C27<>"", $C$70 * I43/$I$49, "") | L43: Terrain Cat. | M43: 2 | Q43: d/b | R43: =R40/R41 -> 0.875
B44: Sα | C44: =C40*C41*C37 -> 0 | E44: 5 | F44: =IF(C28<>"", L28*$C$3*$C$7, "") | G44: =IF(C28<>"", F44/$C$10, "") | I44: =IF(C28<>"", G44*G28, "") | J44: =IF(C28<>"", $C$70 * I44/$I$49, "") | L44: z_0 | M44: 1 | N44: m | Q44: h/b | R44: =R39/R41 -> 0.4375
B45: Sϐ | C45: =C40*C42*C38 -> 0 | E45: 6 | F45: =IF(C29<>"", L29*$C$3*$C$7, "") | G45: =IF(C29<>"", F45/$C$10, "") | I45: =IF(C29<>"", G45*G29, "") | J45: =IF(C29<>"", $C$70 * I45/$I$49, "") | L45: z_min | M45: 10 | N45: m | Q45: c_pe_wind | R45: =IF(R42>=1, 0.8, IF(AND(R42<1, R42>0.25), 0.8-0.1333*R42, 0.7)) -> 0.73335
E46: 7 | F46: =IF(C30<>"", L30*$C$3*$C$7, "") | G46: =IF(C30<>"", F46/$C$10, "") | I46: =IF(C30<>"", G46*G30, "") | J46: =IF(C30<>"", $C$70 * I46/$I$49, "") | L46: alpha | M46: =0.67+0.05*LN(M44) -> 0.67 | Q46: c_pe_lee | R46: =IF(R42>5, -0.7, IF(AND(R42>1, R42<=5), -0.7+0.05*(5-R42), IF(AND(R42>0.25, R42<=1), -0.5+0.2667*(1-R42), -0.3))) -> -0.36665
B47: F_A | C47: 2.5 | E47: 8 | F47: =IF(C31<>"", L31*$C$3*$C$7, "") | G47: =IF(C31<>"", F47/$C$10, "") | I47: =IF(C31<>"", G47*G31, "") | J47: =IF(C31<>"", $C$70 * I47/$I$49, "") | L47: Topography | M47: Flat | Q47: zs | R47: =MAX(0.6*R39, M45) -> 10 | S47: m
...

Sheet Cross Sections and Materials
B3: Beams | P3: Materials
B4: Section | C4: Seciton Class | D4: Mel,Rd [kNcm] | E4: Mpl,Rd [kNcm] | F4: Npl,Rd [kN] | G4: h [cm] | H4: b [cm] | I4: tw [cm] | J4: tf [cm] | K4: A [cm²] | L4: Iy [cm4] | M4: hw [cm] | P4: fy | Q4: 23.5 | R4: kN/cm²
B5: IPE 360 | C5: 2 | D5: 21240 | E5: 23950 | F5: 1709 | G5: 36 | H5: 17 | I5: 0.8 | J5: 1.27 | K5: 72.7 | L5: 16270 | M5: =G5-2*J5 -> 33.46 | P5: E | Q5: 21000 | R5: kN/cm²
P6: γM0 | Q6: 1
B7: Columns | P7: γM1 | Q7: 1.1
B8: Section | C8: h [cm] | D8: b [cm] | E8: tw [cm] | F8: tf [cm] | G8: A [cm²] | H8: Iy [cm4] | I8: i_y [cm] | J8: i_z [cm] | K8: αy | L8: αz | M8: M_pl,Rd [kNcm] | N8: hw [cm] | P8: λ1 | Q8: 93.9
B9: HEB 650 | C9: 65 | D9: 30 | E9: 1.7 | F9: 3.2 | G9: 286.3 | H9: 256900 | I9: 29 | J9: 6.87 | K9: 0.21 | L9: 0.34 | M9: 172020 | N9: =C9-2*F9 -> 58.6 | P9: ωrm | Q9: 1.45
P10: ωsh | Q10: 1.1
B11: Braces
B12: Storey | C12: Section | D12: D [mm] | E12: t [mm] | F12: A [cm²] | G12: i [cm] | H12: Iy [cm4] | I12: α | J12: M_pl,Rd [kNcm]
B13: 1 | C13: CHS 193.7x6 | D13: 193.7 | E13: 6 | F13: 35.38 | G13: 6.64 | H13: 1560 | I13: 0.49 | J13: 4970.3
B14: 2 | C14: CHS 193.7x6 | D14: 193.7 | E14: 6 | F14: 35.38 | G14: 6.64 | H14: 1560 | I14: 0.49 | J14: 4970.3
B15: 3 | C15: CHS 177.8x6.3 | D15: 177.8 | E15: 6.3 | F15: 32.38 | G15: 6.08 | H15: 1196 | I15: 0.49 | J15: 4164.2
B16: 4
B17: 5
B18: 6
B19: 7
B20: 8
B21: 9

Sheet Nonseismic_Design
B3: fy | C3: ='Cross Sections and Materials'!Q4 -> 23.5 | D3: kN/cm²
B4: gamma_M0 | C4: ='Cross Sections and Materials'!Q6 -> 1
B5: gamma_M1 | C5: ='Cross Sections and Materials'!Q7 -> 1.1
B6: λ1 | C6: ='Cross Sections and Materials'!Q8 -> 93.9
B8: Beams
B9: --> The sign for the axial force is reversed so that it corresponds with the opensees code (-ve values at end i are tension, +ve values are compression)
B11: Demands | H11: Verification
B12: Stab | C12: 22 | D12: M_Ed | E12: N_Ed | F12: V_Ed | H12: Section | I12: Mpl,Rd | J12: Npl,Rd | K12: b | L12: tw | M12: tf | N12: A | O12: hw
B13: LC1 | C13: G+Q | D13: 13440 | E13: -30.97 | F13: 0 | H13: ='Cross Sections and Materials'!B5 -> IPE 360 | I13: ='Cross Sections and Materials'!E5 -> 23950 | J13: ='Cross Sections and Materials'!F5 -> 1709 | K13: ='Cross Sections and Materials'!H5 -> 17 | L13: ='Cross Sections and Materials'!I5 -> 0.8 | M13: ='Cross Sections and Materials'!J5 -> 1.27 | N13: ='Cross Sections and Materials'!K5 -> 72.7 | O13: ='Cross Sections and Materials'!M5 -> 33.46
C14: W | D14: 0 | E14: -67.3 | F14: 0
C15: I | I15: M_Ed | J15: N_Ed | K15: M-N int | L15: n | M15: a* | N15: M_N,Rd | O15: ηN | P15: ηM
C16: Σ | D16: =SUM(D13:D15) -> 13440 | E16: =SUM(E13:E15) -> -98.27 | F16: =SUM(F13:F15) -> 0 | H16: LC1 | I16: =D16 -> 13440 | J16: =E16 -> -98.27 | K16: =IF(MIN(0.25*J13, 0.5*O13*L13*$C$3/$C$4) < ABS(J16), "JA", "NEIN") -> NEIN | L16: =IF(K16="JA", ABS(J16)/$J$13, 0) -> 0 | M16: =IF(K16="JA", MIN(($N$13-2*$K$13*$M$13)/$N$13, 0.5), 0) -> 0 | N16: =MIN($I$13, $I$13*(1-L16)/(1-0.5*M16)) -> 23950 | O16: =ABS(J16)/$J$13 -> 0.057501463 | P16: =I16/N16 -> 0.5611691 | Q16: =IF(P16<1,"OK!","NG!") -> OK!
H17: LC2 | I17: =D22 -> 12190 | J17: =E22 -> -140.09 | K17: =IF(MIN(0.25*J13, 0.5*O13*L13*$C$3/$C$4) < ABS(J17), "JA", "NEIN") -> NEIN | L17: =IF(K17="JA", ABS(J17)/$J$13, 0) -> 0 | M17: =IF(K17="JA", MIN(($N$13-2*$K$13*$M$13)/$N$13, 0.5), 0) -> 0 | N17: =MIN($I$13, $I$13*(1-L17)/(1-0.5*M17)) -> 23950 | O17: =ABS(J17)/$J$13 -> 0.081971913 | P17: =I17/N17 -> 0.50897704 | Q17: =IF(P17<1,"OK!","NG!") -> OK!
B18: Stab | C18: 22 | D18: M_Ed | E18: N_Ed | F18: V_Ed
B19: LC2 | C19: G+Q | D19: 12190 | E19: -28.49 | F19: 0
C20: W | D20: 0 | E20: -111.6 | F20: 0
C21: I
C22: Σ | D22: =SUM(D19:D21) -> 12190 | E22: =SUM(E19:E21) -> -140.09 | F22: =SUM(F19:F21) -> 0
B24: Columns
B26: Demands | H26: Verification
B27: Stab | C27: 2 | D27: M_Ed | E27: N_Ed | F27: V_Ed | H27: Section | I27: A [cm²] | J27: i [cm] | K27: α | L27: L [cm] | M27: β | N27: Lcr [cm] | O27: λ_bar | P27: Φ | Q27: χ | R27: Nb,Rd [kN]
B28: LC1 | C28: G+Q | D28: 158 | E28: 1642 | F28: 0 | H28: ='Cross Sections and Materials'!B9 -> HEB 650 | I28: ='Cross Sections and Materials'!G9 -> 286.3 | J28: ='Cross Sections and Materials'!J9 -> 6.87 | K28: ='Cross Sections and Materials'!L9 -> 0.34 | L28: 350 | M28: 1 | N28: =M28*L28 -> 350 | O28: =N28/J28/$C$6 -> 0.54255743 | P28: =0.5*(1+K28*(O28-0.2)+O28^2) -> 0.70541905 | Q28: =MIN(1/(P28+SQRT(P28^2-O28^2)), 1) -> 0.86486576 | R28: =Q28*I28*$C$3/$C$5 -> 5289.8728
C29: W | D29: -1115 | E29: 125.7 | F29: 0
C30: I | I30: N_Ed | J30: η
C31: Σ | D31: =SUM(D28:D30) -> -957 | E31: =SUM(E28:E30) -> 1767.7 | F31: =SUM(F28:F30) -> 0 | H31: LC1 | I31: =E31 -> 1767.7 | J31: =I31/$R$28 -> 0.33416682 | K31: =IF(J31<1,"OK!","NG!") -> OK!
H32: LC2 | I32: =E37 -> 1717.5 | J32: =I32/$R$28 -> 0.32467699 | K32: =IF(J32<1,"OK!","NG!") -> OK!
B33: Stab | C33: 2 | D33: M_Ed | E33: N_Ed | F33: V_Ed
B34: LC2 | C34: G+Q | D34: 145.3 | E34: 1509 | F34: 0 | H34: --> maximum compression force is larger than the maximum tension force.
C35: W | D35: -1849 | E35: 208.5 | F35: 0 | H35: --> The fact that the buckling check passes means that the tension check on the same section will pass as well
C36: I
C37: Σ | D37: =SUM(D34:D36) -> -1703.7 | E37: =SUM(E34:E36) -> 1717.5 | F37: =SUM(F34:F36) -> 0
B39: Braces - L1
B41: Demands | D41: Tension / min. Compression | H41: Demands | J41: max. Compression | N41: Verification
B42: Stab | C42: 30 | D42: M_Ed | E42: N_Ed | F42: V_Ed | H42: Stab | I42: 33 | J42: M_Ed | K42: N_Ed | L42: V_Ed | N42: Section | O42: h [cm] | P42: l [cm] | Q42: A [cm²] | R42: i [cm] | S42: α | T42: L [cm] | U42: Lcr [cm] | V42: λ_bar | W42: Φ | X42: χ | Y42: Npl,Rd [kN] | Z42: Nb,Rd [kN]
B43: LC1 | C43: G+Q | D43: 0 | E43: 39.89 | F43: 0 | H43: LC1 | I43: G+Q | J43: 0 | K43: 39.89 | L43: 0 | N43: ='Cross Sections and Materials'!C13 -> CHS 193.7x6 | O43: 350 | P43: 700 | Q43: ='Cross Sections and Materials'!F13 -> 35.38 | R43: ='Cross Sections and Materials'!G13 -> 6.64 | S43: ='Cross Sections and Materials'!I13 -> 0.49 | T43: =SQRT(O43^2+P43^2) -> 782.62379 | U43: =0.8*T43 -> 626.09903 | V43: =U43/R43/$C$6 -> 1.0041749 | W43: =0.5*(1+S43*(V43-0.2)+V43^2) -> 1.2012065 | X43: =MIN(1/(W43+SQRT(W43^2-V43^2)), 1) -> 0.53752021 | Y43: =Q43*$C$3/$C$4 -> 831.43 | Z43: =X43*Q43*$C$3/$C$5 -> 406.28221
C44: W | D44: 0 | E44: -87.26 | F44: 0 | I44: W | J44: 0 | K44: 86.42 | L44: 0
C45: I | I45: I | O45: Compression | S45: Tension
C46: Σ | D46: =SUM(D43:D45) -> 0 | E46: =SUM(E43:E45) -> -47.37 | F46: =SUM(F43:F45) -> 0 | I46: Σ | J46: =SUM(J43:J45) -> 0 | K46: =SUM(K43:K45) -> 126.31 | L46: =SUM(L43:L45) -> 0 | O46: N_Ed | P46: η | S46: N_Ed | T46: η
N47: LC1 | O47: =K46 -> 126.31 | P47: =O47/$Z$43 -> 0.31089228 | Q47: =IF(P47<1,"OK!","NG!") -> OK! | S47: =ABS(MIN(E46,0)) -> 47.37 | T47: =S47/$Y$43 -> 0.056974129 | U47: =IF(T47<1,"OK!","NG!") -> OK!
B48: Stab | C48: 30 | D48: M_Ed | E48: N_Ed | F48: V_Ed | H48: Stab | I48: 33 | J48: M_Ed | K48: N_Ed | L48: V_Ed | N48: LC2 | O48: =K52 -> 179.96 | P48: =O48/$Z$43 -> 0.44294335 | Q48: =IF(P48<1,"OK!","NG!") -> OK! | S48: =ABS(MIN(E52,0)) -> 107.94 | T48: =S48/$Y$43 -> 0.12982452 | U48: =IF(T48<1,"OK!","NG!") -> OK!
...
