Workbook
Name T: Loads!$C$63
Name TA: Loads!$C$49
Name TB: Loads!$C$50
Name TC: Loads!$C$51
Name TD: Loads!$C$52

Sheet Loads
B2: General Building Geometry
B3: Building Width | C3: 21 | D3: m
B4: Building Depth | C4: 24 | D4: m
B5: Beam Trib width | C5: 1.5 | D5: m | E5: <-- tributary width for beam UDL for gravity loads
B6: Frame Trib width | C6: 3 | D6: m | E6: <-- tributary width for gravity loads
B7: Lateral Trib width | C7: 6 | D7: m | E7: <-- tributary width for seismic mass / lateral loads
B8: No. Storeys | C8: =COUNT(C24:C32) -> 9
B10: g | C10: =9.81 -> 9.81 | D10: m/s²
B12: Partial Safety Factors and Combination Factors
C13: G | D13: Q | E13: W | F13: S | G13: I
B14: γ | C14: 1.35 | D14: 1.5 | E14: 1.5 | F14: 1.5
B15: ψ0 | D15: 0.7 | E15: 0.6 | F15: 0.5
B16: ψ1 | D16: 0.5 | E16: 0.2 | F16: 0.2
B17: ψ2 | D17: 0.3 | E17: 0 | F17: 0
B18: φ | D18: 1
B19: ψE | D19: =D18*D17 -> 0.3
B21: Floor Loads | S21: Snow Loads --> EC1-3:2010
I22: Floor Loads [kPa] | N22: Beam UDLs [kN/m]
B23: Storey | C23: G [kPa] | D23: Q [kPa] | E23: S [kPa] | F23: hi [m] | G23: Hi [m] | I23: LC1 - GQWSI | J23: LC2 - GQWSI | K23: LC3 - GQWSI | L23: LC4 - GQEI | N23: GQWSI | O23: GWQSI | P23: GSQWI | Q23: GQEI | S23: Ground snow load | T23: sk | U23: 0.85 | V23: kPa
B24: 1 | C24: 7.5 | D24: 3 | E24: =IF(C24<>"", IF(G24=MAX($G$24:$G$32), $U$29, 0), "") -> 0 | F24: 3.5 | G24: =IF(C24<>"", SUM($F$24:F24), "") -> 3.5 | I24: =IF(C24<>"", $C$14*C24+$D$14*D24+$F$14*$F$15*E24, "") -> 14.625 | J24: =IF(C24<>"", $C$14*C24 + $D$14*$D$15*D24 + $F$14*$F$15*E24, "") -> 13.275 | K24: =IF(C24<>"", $C$14*C24 + $D$14*$D$15*D24 + $F$14*E24, "") -> 13.275 | L24: =IF(C24<>"", C24+$D$19*D24, "") -> 8.4 | N24: =IF(C24<>"", I24*$C$5, "") -> 21.9375 | O24: =IF(C24<>"", J24*$C$5, "") -> 19.9125 | P24: =IF(C24<>"", K24*$C$5, "") -> 19.9125 | Q24: =IF(C24<>"", L24*$C$5, "") -> 12.6 | S24: Roof slope | T24: α | U24: 4 | V24: °
B25: 2 | C25: 7.5 | D25: 3 | E25: =IF(C25<>"", IF(G25=MAX($G$24:$G$32), $U$29, 0), "") -> 0 | F25: 3.5 | G25: =IF(C25<>"", SUM($F$24:F25), "") -> 7 | I25: =IF(C25<>"", $C$14*C25+$D$14*D25+$F$14*$F$15*E25, "") -> 14.625 | J25: =IF(C25<>"", $C$14*C25 + $D$14*$D$15*D25 + $F$14*$F$15*E25, "") -> 13.275 | K25: =IF(C25<>"", $C$14*C25 + $D$14*$D$15*D25 + $F$14*E25, "") -> 13.275 | L25: =IF(C25<>"", C25+$D$19*D25, "") -> 8.4 | N25: =IF(C25<>"", I25*$C$5, "") -> 21.9375 | O25: =IF(C25<>"", J25*$C$5, "") -> 19.9125 | P25: =IF(C25<>"", K25*$C$5, "") -> 19.9125 | Q25: =IF(C25<>"", L25*$C$5, "") -> 12.6 | T25: Ce | U25: 1
B26: 3 | C26: 7.5 | D26: 3 | E26: =IF(C26<>"", IF(G26=MAX($G$24:$G$32), $U$29, 0), "") -> 0 | F26: 3.5 | G26: =IF(C26<>"", SUM($F$24:F26), "") -> 10.5 | I26: =IF(C26<>"", $C$14*C26+$D$14*D26+$F$14*$F$15*E26, "") -> 14.625 | J26: =IF(C26<>"", $C$14*C26 + $D$14*$D$15*D26 + $F$14*$F$15*E26, "") -> 13.275 | K26: =IF(C26<>"", $C$14*C26 + $D$14*$D$15*D26 + $F$14*E26, "") -> 13.275 | L26: =IF(C26<>"", C26+$D$19*D26, "") -> 8.4 | N26: =IF(C26<>"", I26*$C$5, "") -> 21.9375 | O26: =IF(C26<>"", J26*$C$5, "") -> 19.9125 | P26: =IF(C26<>"", K26*$C$5, "") -> 19.9125 | Q26: =IF(C26<>"", L26*$C$5, "") -> 12.6 | T26: Ct | U26: 1
B27: 4 | C27: 7.5 | D27: 3 | E27: =IF(C27<>"", IF(G27=MAX($G$24:$G$32), $U$29, 0), "") -> 0 | F27: 3.5 | G27: =IF(C27<>"", SUM($F$24:F27), "") -> 14 | I27: =IF(C27<>"", $C$14*C27+$D$14*D27+$F$14*$F$15*E27, "") -> 14.625 | J27: =IF(C27<>"", $C$14*C27 + $D$14*$D$15*D27 + $F$14*$F$15*E27, "") -> 13.275 | K27: =IF(C27<>"", $C$14*C27 + $D$14*$D$15*D27 + $F$14*E27, "") -> 13.275 | L27: =IF(C27<>"", C27+$D$19*D27, "") -> 8.4 | N27: =IF(C27<>"", I27*$C$5, "") -> 21.9375 | O27: =IF(C27<>"", J27*$C$5, "") -> 19.9125 | P27: =IF(C27<>"", K27*$C$5, "") -> 19.9125 | Q27: =IF(C27<>"", L27*$C$5, "") -> 12.6
B28: 5 | C28: 7.5 | D28: 3 | E28: =IF(C28<>"", IF(G28=MAX($G$24:$G$32), $U$29, 0), "") -> 0 | F28: 3.5 | G28: =IF(C28<>"", SUM($F$24:F28), "") -> 17.5 | I28: =IF(C28<>"", $C$14*C28+$D$14*D28+$F$14*$F$15*E28, "") -> 14.625 | J28: =IF(C28<>"", $C$14*C28 + $D$14*$D$15*D28 + $F$14*$F$15*E28, "") -> 13.275 | K28: =IF(C28<>"", $C$14*C28 + $D$14*$D$15*D28 + $F$14*E28, "") -> 13.275 | L28: =IF(C28<>"", C28+$D$19*D28, "") -> 8.4 | N28: =IF(C28<>"", I28*$C$5, "") -> 21.9375 | O28: =IF(C28<>"", J28*$C$5, "") -> 19.9125 | P28: =IF(C28<>"", K28*$C$5, "") -> 19.9125 | Q28: =IF(C28<>"", L28*$C$5, "") -> 12.6 | S28: Shape factor | T28: μ1 | U28: =IF(U24<30, 0.8, IF(U24<60, 0.8*(60-U24)/30, 0)) -> 0.8 | V28: kPa
B29: 6 | C29: 7.5 | D29: 3 | E29: =IF(C29<>"", IF(G29=MAX($G$24:$G$32), $U$29, 0), "") -> 0 | F29: 3.5 | G29: =IF(C29<>"", SUM($F$24:F29), "") -> 21 | I29: =IF(C29<>"", $C$14*C29+$D$14*D29+$F$14*$F$15*E29, "") -> 14.625 | J29: =IF(C29<>"", $C$14*C29 + $D$14*$D$15*D29 + $F$14*$F$15*E29, "") -> 13.275 | K29: =IF(C29<>"", $C$14*C29 + $D$14*$D$15*D29 + $F$14*E29, "") -> 13.275 | L29: =IF(C29<>"", C29+$D$19*D29, "") -> 8.4 | N29: =IF(C29<>"", I29*$C$5, "") -> 21.9375 | O29: =IF(C29<>"", J29*$C$5, "") -> 19.9125 | P29: =IF(C29<>"", K29*$C$5, "") -> 19.9125 | Q29: =IF(C29<>"", L29*$C$5, "") -> 12.6 | S29: Roof snow load | T29: s | U29: =U28*U25*U26*U23 -> 0.68 | V29: kPa
B30: 7 | C30: 7.5 | D30: 3 | E30: =IF(C30<>"", IF(G30=MAX($G$24:$G$32), $U$29, 0), "") -> 0 | F30: 3.5 | G30: =IF(C30<>"", SUM($F$24:F30), "") -> 24.5 | I30: =IF(C30<>"", $C$14*C30+$D$14*D30+$F$14*$F$15*E30, "") -> 14.625 | J30: =IF(C30<>"", $C$14*C30 + $D$14*$D$15*D30 + $F$14*$F$15*E30, "") -> 13.275 | K30: =IF(C30<>"", $C$14*C30 + $D$14*$D$15*D30 + $F$14*E30, "") -> 13.275 | L30: =IF(C30<>"", C30+$D$19*D30, "") -> 8.4 | N30: =IF(C30<>"", I30*$C$5, "") -> 21.9375 | O30: =IF(C30<>"", J30*$C$5, "") -> 19.9125 | P30: =IF(C30<>"", K30*$C$5, "") -> 19.9125 | Q30: =IF(C30<>"", L30*$C$5, "") -> 12.6
B31: 8 | C31: 7.5 | D31: 3 | E31: =IF(C31<>"", IF(G31=MAX($G$24:$G$32), $U$29, 0), "") -> 0 | F31: 3.5 | G31: =IF(C31<>"", SUM($F$24:F31), "") -> 28 | I31: =IF(C31<>"", $C$14*C31+$D$14*D31+$F$14*$F$15*E31, "") -> 14.625 | J31: =IF(C31<>"", $C$14*C31 + $D$14*$D$15*D31 + $F$14*$F$15*E31, "") -> 13.275 | K31: =IF(C31<>"", $C$14*C31 + $D$14*$D$15*D31 + $F$14*E31, "") -> 13.275 | L31: =IF(C31<>"", C31+$D$19*D31, "") -> 8.4 | N31: =IF(C31<>"", I31*$C$5, "") -> 21.9375 | O31: =IF(C31<>"", J31*$C$5, "") -> 19.9125 | P31: =IF(C31<>"", K31*$C$5, "") -> 19.9125 | Q31: =IF(C31<>"", L31*$C$5, "") -> 12.6
B32: 9 | C32: 7.5 | D32: 0 | E32: =IF(C32<>"", IF(G32=MAX($G$24:$G$32), $U$29, 0), "") -> 0.68 | F32: 3.5 | G32: =IF(C32<>"", SUM($F$24:F32), "") -> 31.5 | I32: =IF(C32<>"", $C$14*C32+$D$14*D32+$F$14*$F$15*E32, "") -> 10.635 | J32: =IF(C32<>"", $C$14*C32 + $D$14*$D$15*D32 + $F$14*$F$15*E32, "") -> 10.635 | K32: =IF(C32<>"", $C$14*C32 + $D$14*$D$15*D32 + $F$14*E32, "") -> 11.145 | L32: =IF(C32<>"", C32+$D$19*D32, "") -> 7.5 | N32: =IF(C32<>"", I32*$C$5, "") -> 15.9525 | O32: =IF(C32<>"", J32*$C$5, "") -> 15.9525 | P32: =IF(C32<>"", K32*$C$5, "") -> 16.7175 | Q32: =IF(C32<>"", L32*$C$5, "") -> 11.25
B36: Seismic Loads --> EC8-1-1:2022 | L36: Wind Loads --> EC1-4:2010
B37: S_alpha_475 | C37: 0 | D37: g | L37: ρ | M37: 1.25 | N37: kg/m³ | Q37: k_r | R37: =0.19*(M44/0.05)^0.07 -> 0.23432882
B38: S_beta_475 | C38: =0.3*C37 -> 0 | D38: g | L38: Windzone | M38: 2 | Q38: v_b | R38: =M39*M41*M42 -> 25 | S38: m/s
B39: Soil Class | C39: C | E39: Storey | F39: W_i [kN] | G39: m_i [t] | I39: mi * Hi | J39: F_i [kN] | L39: v_b0 | M39: 25 | N39: m/s | Q39: h | R39: =SUM(F24:F32) -> 31.5 | S39: m | T39: <-- check this is the correct height
B40: FT | C40: 1 | E40: 1 | F40: =IF(C24<>"", L24*$C$3*$C$7, "") -> 1058.4 | G40: =IF(C24<>"", F40/$C$10, "") -> 107.88991 | I40: =IF(C24<>"", G40*G24, "") -> 377.61468 | J40: =IF(C24<>"", $C$70 * I40/$I$49, "") -> 0 | L40: q_b0 | M40: 0.39 | N40: m/s | Q40: d | R40: =C3 -> 21 | S40: m
B41: F_alpha | C41: =1.6*(1-0.2*C37) -> 1.6 | E41: 2 | F41: =IF(C25<>"", L25*$C$3*$C$7, "") -> 1058.4 | G41: =IF(C25<>"", F41/$C$10, "") -> 107.88991 | I41: =IF(C25<>"", G41*G25, "") -> 755.22936 | J41: =IF(C25<>"", $C$70 * I41/$I$49, "") -> 0 | L41: c_dir | M41: 1 | Q41: b | R41: =C4 -> 24 | S41: m
B42: F_beta | C42: =2.3*(1-0.3*C38) -> 2.3 | E42: 3 | F42: =IF(C26<>"", L26*$C$3*$C$7, "") -> 1058.4 | G42: =IF(C26<>"", F42/$C$10, "") -> 107.88991 | I42: =IF(C26<>"", G42*G26, "") -> 1132.844 | J42: =IF(C26<>"", $C$70 * I42/$I$49, "") -> 0 | L42: c_season | M42: 1 | Q42: h/d | R42: =R39/R40 -> 1.5
E43: 4 | F43: =IF(C27<>"", L27*$C$3*$C$7, "") -> 1058.4 | G43: =IF(C27<>"", F43/$C$10, "") -> 107.88991 | I43: =IF(C27<>"", G43*G27, "") -> 1510.4587 | J43: =IF(C27<>"", $C$70 * I43/$I$49, "") -> 0 | L43: Terrain Cat. | M43: 2 | Q43: d/b | R43: =R40/R41 -> 0.875
B44: Sα | C44: =C40*C41*C37 -> 0 | E44: 5 | F44: =IF(C28<>"", L28*$C$3*$C$7, "") -> 1058.4 | G44: =IF(C28<>"", F44/$C$10, "") -> 107.88991 | I44: =IF(C28<>"", G44*G28, "") -> 1888.0734 | J44: =IF(C28<>"", $C$70 * I44/$I$49, "") -> 0 | L44: z_0 | M44: 1 | N44: m | Q44: h/b | R44: =R39/R41 -> 1.3125
B45: Sϐ | C45: =C40*C42*C38 -> 0 | E45: 6 | F45: =IF(C29<>"", L29*$C$3*$C$7, "") -> 1058.4 | G45: =IF(C29<>"", F45/$C$10, "") -> 107.88991 | I45: =IF(C29<>"", G45*G29, "") -> 2265.6881 | J45: =IF(C29<>"", $C$70 * I45/$I$49, "") -> 0 | L45: z_min | M45: 10 | N45: m | Q45: c_pe_wind | R45: =IF(R42>=1, 0.8, IF(AND(R42<1, R42>0.25), 0.8-0.1333*R42, 0.7)) -> 0.8
E46: 7 | F46: =IF(C30<>"", L30*$C$3*$C$7, "") -> 1058.4 | G46: =IF(C30<>"", F46/$C$10, "") -> 107.88991 | I46: =IF(C30<>"", G46*G30, "") -> 2643.3028 | J46: =IF(C30<>"", $C$70 * I46/$I$49, "") -> 0 | L46: alpha | M46: =0.67+0.05*LN(M44) -> 0.67 | Q46: c_pe_lee | R46: =IF(R42>5, -0.7, IF(AND(R42>1, R42<=5), -0.7+0.05*(5-R42), IF(AND(R42>0.25, R42<=1), -0.5+0.2667*(1-R42), -0.3))) -> -0.525
B47: F_A | C47: 2.5 | E47: 8 | F47: =IF(C31<>"", L31*$C$3*$C$7, "") -> 1058.4 | G47: =IF(C31<>"", F47/$C$10, "") -> 107.88991 | I47: =IF(C31<>"", G47*G31, "") -> 3020.9174 | J47: =IF(C31<>"", $C$70 * I47/$I$49, "") -> 0 | L47: Topography | M47: Flat | Q47: zs | R47: =MAX(0.6*R39, M45) -> 18.9 | S47: m
...

Sheet Cross Sections and Materials
B3: Beams | P3: Materials
B4: Section | C4: Seciton Class | D4: Mel,Rd [kNcm] | E4: Mpl,Rd [kNcm] | F4: Npl,Rd [kN] | G4: h [cm] | H4: b [cm] | I4: tw [cm] | J4: tf [cm] | K4: A [cm²] | L4: Iy [cm4] | M4: hw [cm] | P4: fy | Q4: 23.5 | R4: kN/cm²
B5: IPE 360 | C5: 2 | D5: 21240 | E5: 23950 | F5: 1709 | G5: 36 | H5: 17 | I5: 0.8 | J5: 1.27 | K5: 72.7 | L5: 16270 | M5: =G5-2*J5 -> 33.46 | P5: E | Q5: 21000 | R5: kN/cm²
P6: γM0 | Q6: 1
B7: Columns | P7: γM1 | Q7: 1.1
B8: Section | C8: h [cm] | D8: b [cm] | E8: tw [cm] | F8: tf [cm] | G8: A [cm²] | H8: Iy [cm4] | I8: i_y [cm] | J8: i_z [cm] | K8: αy | L8: αz | M8: M_pl,Rd [kNcm] | N8: hw [cm] | P8: λ1 | Q8: 93.9
B9: HEB 650 | C9: 65 | D9: 30 | E9: 1.7 | F9: 3.2 | G9: 286.3 | H9: 256900 | I9: 29 | J9: 6.87 | K9: 0.21 | L9: 0.34 | M9: 172020 | N9: =C9-2*F9 -> 58.6 | P9: ωrm | Q9: 1.45
P10: ωsh | Q10: 1.1
B11: Braces
B12: Storey | C12: Section | D12: D [mm] | E12: t [mm] | F12: A [cm²] | G12: i [cm] | H12: Iy [cm4] | I12: α | J12: M_pl,Rd [kNcm]
B13: 1 | C13: CHS 193.7x6 | D13: 193.7 | E13: 6 | F13: 35.38 | G13: 6.64 | H13: 1560 | I13: 0.49 | J13: 4970.3
B14: 2 | C14: CHS 193.7x6 | D14: 193.7 | E14: 6 | F14: 35.38 | G14: 6.64 | H14: 1560 | I14: 0.49 | J14: 4970.3
B15: 3 | C15: CHS 177.8x6.3 | D15: 177.8 | E15: 6.3 | F15: 32.38 | G15: 6.08 | H15: 1196 | I15: 0.49 | J15: 4164.2
B16: 4
B17: 5
B18: 6
B19: 7
B20: 8
B21: 9
