Workbook
Name T: Loads!$C$63
Name TA: Loads!$C$49
Name TB: Loads!$C$50
Name TC: Loads!$C$51
Name TD: Loads!$C$52

Sheet Loads
B2: General Building Geometry
B3: Building Width | C3: 21 | D3: m
B4: Building Depth | C4: 24 | D4: m
B5: Beam Trib width | C5: 1.5 | D5: m | E5: <-- tributary width for beam UDL for gravity loads
B6: Frame Trib width | C6: 3 | D6: m | E6: <-- tributary width for gravity loads
B7: Lateral Trib width | C7: 6 | D7: m | E7: <-- tributary width for seismic mass / lateral loads
B8: No. Storeys | C8: =COUNT(C24:C32) -> 6
B10: g | C10: =9.81 -> 9.81 | D10: m/s²
B12: Partial Safety Factors and Combination Factors
C13: G | D13: Q | E13: W | F13: S | G13: I
B14: γ | C14: 1.35 | D14: 1.5 | E14: 1.5 | F14: 1.5
B15: ψ0 | D15: 0.7 | E15: 0.6 | F15: 0.5
B16: ψ1 | D16: 0.5 | E16: 0.2 | F16: 0.2
B17: ψ2 | D17: 0.3 | E17: 0 | F17: 0
B18: φ | D18: 1
B19: ψE | D19: =D18*D17 -> 0.3
B21: Floor Loads | S21: Snow Loads --> EC1-3:2010
I22: Floor Loads [kPa] | N22: Beam UDLs [kN/m]
B23: Storey | C23: G [kPa] | D23: Q [kPa] | E23: S [kPa] | F23: hi [m] | G23: Hi [m] | I23: LC1 - GQWSI | J23: LC2 - GQWSI | K23: LC3 - GQWSI | L23: LC4 - GQEI | N23: GQWSI | O23: GWQSI | P23: GSQWI | Q23: GQEI | S23: Ground snow load | T23: sk | U23: 0.85 | V23: kPa
B24: 1 | C24: 7.5 | D24: 3 | E24: =IF(C24<>"", IF(G24=MAX($G$24:$G$32), $U$29, 0), "") -> 0 | F24: 3.5 | G24: =IF(C24<>"", SUM($F$24:F24), "") -> 3.5 | I24: =IF(C24<>"", $C$14*C24+$D$14*D24+$F$14*$F$15*E24, "") -> 14.625 | J24: =IF(C24<>"", $C$14*C24 + $D$14*$D$15*D24 + $F$14*$F$15*E24, "") -> 13.275 | K24: =IF(C24<>"", $C$14*C24 + $D$14*$D$15*D24 + $F$14*E24, "") -> 13.275 | L24: =IF(C24<>"", C24+$D$19*D24, "") -> 8.4 | N24: =IF(C24<>"", I24*$C$5, "") -> 21.9375 | O24: =IF(C24<>"", J24*$C$5, "") -> 19.9125 | P24: =IF(C24<>"", K24*$C$5, "") -> 19.9125 | Q24: =IF(C24<>"", L24*$C$5, "") -> 12.6 | S24: Roof slope | T24: α | U24: 4 | V24: °
B25: 2 | C25: 7.5 | D25: 3 | E25: =IF(C25<>"", IF(G25=MAX($G$24:$G$32), $U$29, 0), "") -> 0 | F25: 3.5 | G25: =IF(C25<>"", SUM($F$24:F25), "") -> 7 | I25: =IF(C25<>"", $C$14*C25+$D$14*D25+$F$14*$F$15*E25, "") -> 14.625 | J25: =IF(C25<>"", $C$14*C25 + $D$14*$D$15*D25 + $F$14*$F$15*E25, "") -> 13.275 | K25: =IF(C25<>"", $C$14*C25 + $D$14*$D$15*D25 + $F$14*E25, "") -> 13.275 | L25: =IF(C25<>"", C25+$D$19*D25, "") -> 8.4 | N25: =IF(C25<>"", I25*$C$5, "") -> 21.9375 | O25: =IF(C25<>"", J25*$C$5, "") -> 19.9125 | P25: =IF(C25<>"", K25*$C$5, "") -> 19.9125 | Q25: =IF(C25<>"", L25*$C$5, "") -> 12.6 | T25: Ce | U25: 1
B26: 3 | C26: 7.5 | D26: 3 | E26: =IF(C26<>"", IF(G26=MAX($G$24:$G$32), $U$29, 0), "") -> 0 | F26: 3.5 | G26: =IF(C26<>"", SUM($F$24:F26), "") -> 10.5 | I26: =IF(C26<>"", $C$14*C26+$D$14*D26+$F$14*$F$15*E26, "") -> 14.625 | J26: =IF(C26<>"", $C$14*C26 + $D$14*$D$15*D26 + $F$14*$F$15*E26, "") -> 13.275 | K26: =IF(C26<>"", $C$14*C26 + $D$14*$D$15*D26 + $F$14*E26, "") -> 13.275 | L26: =IF(C26<>"", C26+$D$19*D26, "") -> 8.4 | N26: =IF(C26<>"", I26*$C$5, "") -> 21.9375 | O26: =IF(C26<>"", J26*$C$5, "") -> 19.9125 | P26: =IF(C26<>"", K26*$C$5, "") -> 19.9125 | Q26: =IF(C26<>"", L26*$C$5, "") -> 12.6 | T26: Ct | U26: 1
B27: 4 | C27: 7.5 | D27: 3 | E27: =IF(C27<>"", IF(G27=MAX($G$24:$G$32), $U$29, 0), "") -> 0 | F27: 3.5 | G27: =IF(C27<>"", SUM($F$24:F27), "") -> 14 | I27: =IF(C27<>"", $C$14*C27+$D$14*D27+$F$14*$F$15*E27, "") -> 14.625 | J27: =IF(C27<>"", $C$14*C27 + $D$14*$D$15*D27 + $F$14*$F$15*E27, "") -> 13.275 | K27: =IF(C27<>"", $C$14*C27 + $D$14*$D$15*D27 + $F$14*E27, "") -> 13.275 | L27: =IF(C27<>"", C27+$D$19*D27, "") -> 8.4 | N27: =IF(C27<>"", I27*$C$5, "") -> 21.9375 | O27: =IF(C27<>"", J27*$C$5, "") -> 19.9125 | P27: =IF(C27<>"", K27*$C$5, "") -> 19.9125 | Q27: =IF(C27<>"", L27*$C$5, "") -> 12.6
B28: 5 | C28: 7.5 | D28: 3 | E28: =IF(C28<>"", IF(G28=MAX($G$24:$G$32), $U$29, 0), "") -> 0 | F28: 3.5 | G28: =IF(C28<>"", SUM($F$24:F28), "") -> 17.5 | I28: =IF(C28<>"", $C$14*C28+$D$14*D28+$F$14*$F$15*E28, "") -> 14.625 | J28: =IF(C28<>"", $C$14*C28 + $D$14*$D$15*D28 + $F$14*$F$15*E28, "") -> 13.275 | K28: =IF(C28<>"", $C$14*C28 + $D$14*$D$15*D28 + $F$14*E28, "") -> 13.275 | L28: =IF(C28<>"", C28+$D$19*D28, "") -> 8.4 | N28: =IF(C28<>"", I28*$C$5, "") -> 21.9375 | O28: =IF(C28<>"", J28*$C$5, "") -> 19.9125 | P28: =IF(C28<>"", K28*$C$5, "") -> 19.9125 | Q28: =IF(C28<>"", L28*$C$5, "") -> 12.6 | S28: Shape factor | T28: μ1 | U28: =IF(U24<30, 0.8, IF(U24<60, 0.8*(60-U24)/30, 0)) -> 0.8 | V28: kPa
B29: 6 | C29: 7.5 | D29: 0 | E29: =IF(C29<>"", IF(G29=MAX($G$24:$G$32), $U$29, 0), "") -> 0.68 | F29: 3.5 | G29: =IF(C29<>"", SUM($F$24:F29), "") -> 21 | I29: =IF(C29<>"", $C$14*C29+$D$14*D29+$F$14*$F$15*E29, "") -> 10.635 | J29: =IF(C29<>"", $C$14*C29 + $D$14*$D$15*D29 + $F$14*$F$15*E29, "") -> 10.635 | K29: =IF(C29<>"", $C$14*C29 + $D$14*$D$15*D29 + $F$14*E29, "") -> 11.145 | L29: =IF(C29<>"", C29+$D$19*D29, "") -> 7.5 | N29: =IF(C29<>"", I29*$C$5, "") -> 15.9525 | O29: =IF(C29<>"", J29*$C$5, "") -> 15.9525 | P29: =IF(C29<>"", K29*$C$5, "") -> 16.7175 | Q29: =IF(C29<>"", L29*$C$5, "") -> 11.25 | S29: Roof snow load | T29: s | U29: =U28*U25*U26*U23 -> 0.68 | V29: kPa
B30: 7 | E30: =IF(C30<>"", IF(G30=MAX($G$24:$G$32), $U$29, 0), "") | G30: =IF(C30<>"", SUM($F$24:F30), "") | I30: =IF(C30<>"", $C$14*C30+$D$14*D30+$F$14*$F$15*E30, "") | J30: =IF(C30<>"", $C$14*C30 + $D$14*$D$15*D30 + $F$14*$F$15*E30, "") | K30: =IF(C30<>"", $C$14*C30 + $D$14*$D$15*D30 + $F$14*E30, "") | L30: =IF(C30<>"", C30+$D$19*D30, "") | N30: =IF(C30<>"", I30*$C$5, "") | O30: =IF(C30<>"", J30*$C$5, "") | P30: =IF(C30<>"", K30*$C$5, "") | Q30: =IF(C30<>"", L30*$C$5, "")
B31: 8 | E31: =IF(C31<>"", IF(G31=MAX($G$24:$G$32), $U$29, 0), "") | G31: =IF(C31<>"", SUM($F$24:F31), "") | I31: =IF(C31<>"", $C$14*C31+$D$14*D31+$F$14*$F$15*E31, "") | J31: =IF(C31<>"", $C$14*C31 + $D$14*$D$15*D31 + $F$14*$F$15*E31, "") | K31: =IF(C31<>"", $C$14*C31 + $D$14*$D$15*D31 + $F$14*E31, "") | L31: =IF(C31<>"", C31+$D$19*D31, "") | N31: =IF(C31<>"", I31*$C$5, "") | O31: =IF(C31<>"", J31*$C$5, "") | P31: =IF(C31<>"", K31*$C$5, "") | Q31: =IF(C31<>"", L31*$C$5, "")
B32: 9 | E32: =IF(C32<>"", IF(G32=MAX($G$24:$G$32), $U$29, 0), "") | G32: =IF(C32<>"", SUM($F$24:F32), "") | I32: =IF(C32<>"", $C$14*C32+$D$14*D32+$F$14*$F$15*E32, "") | J32: =IF(C32<>"", $C$14*C32 + $D$14*$D$15*D32 + $F$14*$F$15*E32, "") | K32: =IF(C32<>"", $C$14*C32 + $D$14*$D$15*D32 + $F$14*E32, "") | L32: =IF(C32<>"", C32+$D$19*D32, "") | N32: =IF(C32<>"", I32*$C$5, "") | O32: =IF(C32<>"", J32*$C$5, "") | P32: =IF(C32<>"", K32*$C$5, "") | Q32: =IF(C32<>"", L32*$C$5, "")
B36: Seismic Loads --> EC8-1-1:2022 | L36: Wind Loads --> EC1-4:2010
B37: S_alpha_475 | C37: 0.44 | D37: g | L37: ρ | M37: 1.25 | N37: kg/m³ | Q37: k_r | R37: =0.19*(M44/0.05)^0.07 -> 0.19
B38: S_beta_475 | C38: =0.3*C37 -> 0.132 | D38: g | L38: Windzone | M38: 2 | Q38: v_b | R38: =M39*M41*M42 -> 25 | S38: m/s
B39: Soil Class | C39: C | E39: Storey | F39: W_i [kN] | G39: m_i [t] | I39: mi * Hi | J39: F_i [kN] | L39: v_b0 | M39: 25 | N39: m/s | Q39: h | R39: =SUM(F24:F32) -> 21 | S39: m | T39: <-- check this is the correct height
B40: FT | C40: 1 | E40: 1 | F40: =IF(C24<>"", L24*$C$3*$C$7, "") -> 1058.4 | G40: =IF(C24<>"", F40/$C$10, "") -> 107.88991 | I40: =IF(C24<>"", G40*G24, "") -> 377.61468 | J40: =IF(C24<>"", $C$70 * I40/$I$49, "") -> 28.4936 | L40: q_b0 | M40: 0.39 | N40: m/s | Q40: d | R40: =C3 -> 21 | S40: m
B41: F_alpha | C41: =1.6*(1-0.2*C37) -> 1.4592 | E41: 2 | F41: =IF(C25<>"", L25*$C$3*$C$7, "") -> 1058.4 | G41: =IF(C25<>"", F41/$C$10, "") -> 107.88991 | I41: =IF(C25<>"", G41*G25, "") -> 755.22936 | J41: =IF(C25<>"", $C$70 * I41/$I$49, "") -> 56.987201 | L41: c_dir | M41: 1 | Q41: b | R41: =C4 -> 24 | S41: m
B42: F_beta | C42: =2.3*(1-0.3*C38) -> 2.20892 | E42: 3 | F42: =IF(C26<>"", L26*$C$3*$C$7, "") -> 1058.4 | G42: =IF(C26<>"", F42/$C$10, "") -> 107.88991 | I42: =IF(C26<>"", G42*G26, "") -> 1132.844 | J42: =IF(C26<>"", $C$70 * I42/$I$49, "") -> 85.480801 | L42: c_season | M42: 1 | Q42: h/d | R42: =R39/R40 -> 1
E43: 4 | F43: =IF(C27<>"", L27*$C$3*$C$7, "") -> 1058.4 | G43: =IF(C27<>"", F43/$C$10, "") -> 107.88991 | I43: =IF(C27<>"", G43*G27, "") -> 1510.4587 | J43: =IF(C27<>"", $C$70 * I43/$I$49, "") -> 113.9744 | L43: Terrain Cat. | M43: 2 | Q43: d/b | R43: =R40/R41 -> 0.875
B44: Sα | C44: =C40*C41*C37 -> 0.642048 | E44: 5 | F44: =IF(C28<>"", L28*$C$3*$C$7, "") -> 1058.4 | G44: =IF(C28<>"", F44/$C$10, "") -> 107.88991 | I44: =IF(C28<>"", G44*G28, "") -> 1888.0734 | J44: =IF(C28<>"", $C$70 * I44/$I$49, "") -> 142.468 | L44: z_0 | M44: 0.05 | N44: m | Q44: h/b | R44: =R39/R41 -> 0.875
B45: Sϐ | C45: =C40*C42*C38 -> 0.29157744 | E45: 6 | F45: =IF(C29<>"", L29*$C$3*$C$7, "") -> 945 | G45: =IF(C29<>"", F45/$C$10, "") -> 96.330275 | I45: =IF(C29<>"", G45*G29, "") -> 2022.9358 | J45: =IF(C29<>"", $C$70 * I45/$I$49, "") -> 152.64429 | L45: z_min | M45: 2 | N45: m | Q45: c_pe_wind | R45: =IF(R42>=1, 0.8, IF(AND(R42<1, R42>0.25), 0.8-0.1333*R42, 0.7)) -> 0.8
E46: 7 | F46: =IF(C30<>"", L30*$C$3*$C$7, "") | G46: =IF(C30<>"", F46/$C$10, "") | I46: =IF(C30<>"", G46*G30, "") | J46: =IF(C30<>"", $C$70 * I46/$I$49, "") | L46: alpha | M46: =0.67+0.05*LN(M44) -> 0.52021339 | Q46: c_pe_lee | R46: =IF(R42>5, -0.7, IF(AND(R42>1, R42<=5), -0.7+0.05*(5-R42), IF(AND(R42>0.25, R42<=1), -0.5+0.2667*(1-R42), -0.3))) -> -0.5
B47: F_A | C47: 2.5 | E47: 8 | F47: =IF(C31<>"", L31*$C$3*$C$7, "") | G47: =IF(C31<>"", F47/$C$10, "") | I47: =IF(C31<>"", G47*G31, "") | J47: =IF(C31<>"", $C$70 * I47/$I$49, "") | L47: Topography | M47: Flat | Q47: zs | R47: =MAX(0.6*R39, M45) -> 12.6 | S47: m
...

Sheet Cross Sections and Materials
B3: Beams | P3: Materials
B4: Section | C4: Seciton Class | D4: Mel,Rd [kNcm] | E4: Mpl,Rd [kNcm] | F4: Npl,Rd [kN] | G4: h [cm] | H4: b [cm] | I4: tw [cm] | J4: tf [cm] | K4: A [cm²] | L4: Iy [cm4] | M4: hw [cm] | P4: fy | Q4: 23.5 | R4: kN/cm²
B5: IPE 360 | C5: 2 | D5: 21240 | E5: 23950 | F5: 1709 | G5: 36 | H5: 17 | I5: 0.8 | J5: 1.27 | K5: 72.7 | L5: 16270 | M5: =G5-2*J5 -> 33.46 | P5: E | Q5: 21000 | R5: kN/cm²
P6: γM0 | Q6: 1
B7: Columns | P7: γM1 | Q7: 1.1
B8: Section | C8: h [cm] | D8: b [cm] | E8: tw [cm] | F8: tf [cm] | G8: A [cm²] | H8: Iy [cm4] | I8: i_y [cm] | J8: i_z [cm] | K8: αy | L8: αz | M8: M_pl,Rd [kNcm] | N8: hw [cm] | P8: λ1 | Q8: 93.9
B9: HEB 650 | C9: 65 | D9: 30 | E9: 1.7 | F9: 3.2 | G9: 286.3 | H9: 256900 | I9: 29 | J9: 6.87 | K9: 0.21 | L9: 0.34 | M9: 172020 | N9: =C9-2*F9 -> 58.6 | P9: ωrm | Q9: 1.45
P10: ωsh | Q10: 1.1
B11: Braces
B12: Storey | C12: Section | D12: D [mm] | E12: t [mm] | F12: A [cm²] | G12: i [cm] | H12: Iy [cm4] | I12: α | J12: M_pl,Rd [kNcm]
B13: 1 | C13: CHS 193.7x6 | D13: 193.7 | E13: 6 | F13: 35.38 | G13: 6.64 | H13: 1560 | I13: 0.49 | J13: 4970.3
B14: 2 | C14: CHS 193.7x6 | D14: 193.7 | E14: 6 | F14: 35.38 | G14: 6.64 | H14: 1560 | I14: 0.49 | J14: 4970.3
B15: 3 | C15: CHS 177.8x6.3 | D15: 177.8 | E15: 6.3 | F15: 32.38 | G15: 6.08 | H15: 1196 | I15: 0.49 | J15: 4164.2
B16: 4 | C16: CHS 168.3x6 | D16: 168.3 | E16: 6 | F16: 30.59 | G16: 5.74 | H16: 1009 | I16: 0.49 | J16: 3715.4
B17: 5 | C17: CHS 139.7x6.3 | D17: 139.7 | E17: 6.3 | F17: 26.4 | G17: 4.72 | H17: 588.6 | I17: 0.49 | J17: 2636.7
B18: 6 | C18: CHS 177.8x6.3 | D18: 177.8 | E18: 6.3 | F18: 32.38 | G18: 6.08 | H18: 1196 | I18: 0.49 | J18: 4164.2
B19: 7
B20: 8
B21: 9

Sheet Nonseismic_Design
B3: fy | C3: ='Cross Sections and Materials'!Q4 -> 23.5 | D3: kN/cm²
B4: gamma_M0 | C4: ='Cross Sections and Materials'!Q6 -> 1
B5: gamma_M1 | C5: ='Cross Sections and Materials'!Q7 -> 1.1
B6: λ1 | C6: ='Cross Sections and Materials'!Q8 -> 93.9
B8: Beams
B9: --> The sign for the axial force is reversed so that it corresponds with the opensees code (-ve values at end i are tension, +ve values are compression)
B11: Demands | H11: Verification
B12: Stab | C12: 43 | D12: M_Ed | E12: N_Ed | F12: V_Ed | H12: Section | I12: Mpl,Rd | J12: Npl,Rd | K12: b | L12: tw | M12: tf | N12: A | O12: hw
B13: LC1 | C13: G+Q | D13: 13440 | E13: -30.97 | F13: 0 | H13: ='Cross Sections and Materials'!B5 -> IPE 360 | I13: ='Cross Sections and Materials'!E5 -> 23950 | J13: ='Cross Sections and Materials'!F5 -> 1709 | K13: ='Cross Sections and Materials'!H5 -> 17 | L13: ='Cross Sections and Materials'!I5 -> 0.8 | M13: ='Cross Sections and Materials'!J5 -> 1.27 | N13: ='Cross Sections and Materials'!K5 -> 72.7 | O13: ='Cross Sections and Materials'!M5 -> 33.46
C14: W | D14: 0 | E14: -67.3 | F14: 0
C15: I | I15: M_Ed | J15: N_Ed | K15: M-N int | L15: n | M15: a* | N15: M_N,Rd | O15: ηN | P15: ηM
C16: Σ | D16: =SUM(D13:D15) -> 13440 | E16: =SUM(E13:E15) -> -98.27 | F16: =SUM(F13:F15) -> 0 | H16: LC1 | I16: =D16 -> 13440 | J16: =E16 -> -98.27 | K16: =IF(MIN(0.25*J13, 0.5*O13*L13*$C$3/$C$4) < ABS(J16), "JA", "NEIN") -> NEIN | L16: =IF(K16="JA", ABS(J16)/$J$13, 0) -> 0 | M16: =IF(K16="JA", MIN(($N$13-2*$K$13*$M$13)/$N$13, 0.5), 0) -> 0 | N16: =MIN($I$13, $I$13*(1-L16)/(1-0.5*M16)) -> 23950 | O16: =ABS(J16)/$J$13 -> 0.057501463 | P16: =I16/N16 -> 0.5611691 | Q16: =IF(P16<1,"OK!","NG!") -> OK!
H17: LC2 | I17: =D22 -> 12190 | J17: =E22 -> -140.09 | K17: =IF(MIN(0.25*J13, 0.5*O13*L13*$C$3/$C$4) < ABS(J17), "JA", "NEIN") -> NEIN | L17: =IF(K17="JA", ABS(J17)/$J$13, 0) -> 0 | M17: =IF(K17="JA", MIN(($N$13-2*$K$13*$M$13)/$N$13, 0.5), 0) -> 0 | N17: =MIN($I$13, $I$13*(1-L17)/(1-0.5*M17)) -> 23950 | O17: =ABS(J17)/$J$13 -> 0.081971913 | P17: =I17/N17 -> 0.50897704 | Q17: =IF(P17<1,"OK!","NG!") -> OK!
B18: Stab | C18: 43 | D18: M_Ed | E18: N_Ed | F18: V_Ed
B19: LC2 | C19: G+Q | D19: 12190 | E19: -28.49 | F19: 0
C20: W | D20: 0 | E20: -111.6 | F20: 0
C21: I
C22: Σ | D22: =SUM(D19:D21) -> 12190 | E22: =SUM(E19:E21) -> -140.09 | F22: =SUM(F19:F21) -> 0
B24: Columns
B26: Demands | H26: Verification
B27: Stab | C27: 2 | D27: M_Ed | E27: N_Ed | F27: V_Ed | H27: Section | I27: A [cm²] | J27: i [cm] | K27: α | L27: L [cm] | M27: β | N27: Lcr [cm] | O27: λ_bar | P27: Φ | Q27: χ | R27: Nb,Rd [kN]
B28: LC1 | C28: G+Q | D28: 158 | E28: 1642 | F28: 0 | H28: ='Cross Sections and Materials'!B9 -> HEB 650 | I28: ='Cross Sections and Materials'!G9 -> 286.3 | J28: ='Cross Sections and Materials'!J9 -> 6.87 | K28: ='Cross Sections and Materials'!L9 -> 0.34 | L28: 350 | M28: 1 | N28: =M28*L28 -> 350 | O28: =N28/J28/$C$6 -> 0.54255743 | P28: =0.5*(1+K28*(O28-0.2)+O28^2) -> 0.70541905 | Q28: =MIN(1/(P28+SQRT(P28^2-O28^2)), 1) -> 0.86486576 | R28: =Q28*I28*$C$3/$C$5 -> 5289.8728
C29: W | D29: -1115 | E29: 125.7 | F29: 0
C30: I | I30: N_Ed | J30: η
C31: Σ | D31: =SUM(D28:D30) -> -957 | E31: =SUM(E28:E30) -> 1767.7 | F31: =SUM(F28:F30) -> 0 | H31: LC1 | I31: =E31 -> 1767.7 | J31: =I31/$R$28 -> 0.33416682 | K31: =IF(J31<1,"OK!","NG!") -> OK!
H32: LC2 | I32: =E37 -> 1717.5 | J32: =I32/$R$28 -> 0.32467699 | K32: =IF(J32<1,"OK!","NG!") -> OK!
B33: Stab | C33: 2 | D33: M_Ed | E33: N_Ed | F33: V_Ed
B34: LC2 | C34: G+Q | D34: 145.3 | E34: 1509 | F34: 0 | H34: --> maximum compression force is larger than the maximum tension force.
C35: W | D35: -1849 | E35: 208.5 | F35: 0 | H35: --> The fact that the buckling check passes means that the tension check on the same section will pass as well
C36: I
C37: Σ | D37: =SUM(D34:D36) -> -1703.7 | E37: =SUM(E34:E36) -> 1717.5 | F37: =SUM(F34:F36) -> 0
B39: Braces - L1
B41: Demands | D41: Tension / min. Compression | H41: Demands | J41: max. Compression | N41: Verification
B42: Stab | C42: 70 | D42: M_Ed | E42: N_Ed | F42: V_Ed | H42: Stab | I42: 79 | J42: M_Ed | K42: N_Ed | L42: V_Ed | N42: Section | O42: h [cm] | P42: l [cm] | Q42: A [cm²] | R42: i [cm] | S42: α | T42: L [cm] | U42: Lcr [cm] | V42: λ_bar | W42: Φ | X42: χ | Y42: Npl,Rd [kN] | Z42: Nb,Rd [kN]
B43: LC1 | C43: G+Q | D43: 0 | E43: 39.89 | F43: 0 | H43: LC1 | I43: G+Q | J43: 0 | K43: 39.89 | L43: 0 | N43: ='Cross Sections and Materials'!C13 -> CHS 193.7x6 | O43: 350 | P43: 700 | Q43: ='Cross Sections and Materials'!F13 -> 35.38 | R43: ='Cross Sections and Materials'!G13 -> 6.64 | S43: ='Cross Sections and Materials'!I13 -> 0.49 | T43: =SQRT(O43^2+P43^2) -> 782.62379 | U43: =0.8*T43 -> 626.09903 | V43: =U43/R43/$C$6 -> 1.0041749 | W43: =0.5*(1+S43*(V43-0.2)+V43^2) -> 1.2012065 | X43: =MIN(1/(W43+SQRT(W43^2-V43^2)), 1) -> 0.53752021 | Y43: =Q43*$C$3/$C$4 -> 831.43 | Z43: =X43*Q43*$C$3/$C$5 -> 406.28221
C44: W | D44: 0 | E44: -87.26 | F44: 0 | I44: W | J44: 0 | K44: 86.42 | L44: 0
C45: I | I45: I | O45: Compression | S45: Tension
C46: Σ | D46: =SUM(D43:D45) -> 0 | E46: =SUM(E43:E45) -> -47.37 | F46: =SUM(F43:F45) -> 0 | I46: Σ | J46: =SUM(J43:J45) -> 0 | K46: =SUM(K43:K45) -> 126.31 | L46: =SUM(L43:L45) -> 0 | O46: N_Ed | P46: η | S46: N_Ed | T46: η
N47: LC1 | O47: =K46 -> 126.31 | P47: =O47/$Z$43 -> 0.31089228 | Q47: =IF(P47<1,"OK!","NG!") -> OK! | S47: =ABS(MIN(E46,0)) -> 47.37 | T47: =S47/$Y$43 -> 0.056974129 | U47: =IF(T47<1,"OK!","NG!") -> OK!
B48: Stab | C48: 70 | D48: M_Ed | E48: N_Ed | F48: V_Ed | H48: Stab | I48: 79 | J48: M_Ed | K48: N_Ed | L48: V_Ed | N48: LC2 | O48: =K52 -> 179.96 | P48: =O48/$Z$43 -> 0.44294335 | Q48: =IF(P48<1,"OK!","NG!") -> OK! | S48: =ABS(MIN(E52,0)) -> 107.94 | T48: =S48/$Y$43 -> 0.12982452 | U48: =IF(T48<1,"OK!","NG!") -> OK!
...

Sheet CBF_Seismic_Design_Verification
C2: EC8-1-2:2023 Structural Design Checks
C4: EC8-1-2:2023 §4.4.4.2(1)b Structural regularity --> Stiffness
C5: --> lateral stiffness assumed to be the horizontal component of the brace stiffness
C6: E | D6: ='Cross Sections and Materials'!Q5 -> 21000 | E6: kN/cm²
C7: Storey | D7: Section | E7: h_s | F7: L_bay | G7: A [cm²] | H7: L [cm] | I7: Kbrace [kN/cm] | J7: Kh,i [kN/cm] | K7: Kh,i / Kh,i-1
C8: 1 | D8: =IF(Loads!C24<>"", 'Cross Sections and Materials'!C13, "") -> CHS 193.7x6 | E8: 350 | F8: 700 | G8: =IF(Loads!C24<>"", 'Cross Sections and Materials'!F13, "") -> 35.38 | H8: =IF(Loads!C24<>"", SQRT(E8^2+F8^2), "") -> 782.62379 | I8: =IF(Loads!C24<>"", G8*$D$6/H8, "") -> 949.34502 | J8: =IF(Loads!C24<>"", 2*I8*(F8/H8)^2, "") -> 1518.952
C9: 2 | D9: =IF(Loads!C25<>"", 'Cross Sections and Materials'!C14, "") -> CHS 193.7x6 | E9: 350 | F9: 700 | G9: =IF(Loads!C25<>"", 'Cross Sections and Materials'!F14, "") -> 35.38 | H9: =IF(Loads!C25<>"", SQRT(E9^2+F9^2), "") -> 782.62379 | I9: =IF(Loads!C25<>"", G9*$D$6/H9, "") -> 949.34502 | J9: =IF(Loads!C25<>"", 2*I9*(F9/H9)^2, "") -> 1518.952 | K9: =IF(Loads!C25<>"", J9/J8, "") -> 1 | L9: =IF(Loads!C25<>"", IF(AND(K9>=0.8, K9<=1),"OK!","NG!"), "") -> OK! | M9: <-- must be constant or decrease by not more than 20%
C10: 3 | D10: =IF(Loads!C26<>"", 'Cross Sections and Materials'!C15, "") -> CHS 177.8x6.3 | E10: 350 | F10: 700 | G10: =IF(Loads!C26<>"", 'Cross Sections and Materials'!F15, "") -> 32.38 | H10: =IF(Loads!C26<>"", SQRT(E10^2+F10^2), "") -> 782.62379 | I10: =IF(Loads!C26<>"", G10*$D$6/H10, "") -> 868.84657 | J10: =IF(Loads!C26<>"", 2*I10*(F10/H10)^2, "") -> 1390.1545 | K10: =IF(Loads!C26<>"", J10/J9, "") -> 0.91520633 | L10: =IF(Loads!C26<>"", IF(AND(K10>=0.8, K10<=1),"OK!","NG!"), "") -> OK!
C11: 4 | D11: =IF(Loads!C27<>"", 'Cross Sections and Materials'!C16, "") -> CHS 168.3x6 | E11: 350 | F11: 700 | G11: =IF(Loads!C27<>"", 'Cross Sections and Materials'!F16, "") -> 30.59 | H11: =IF(Loads!C27<>"", SQRT(E11^2+F11^2), "") -> 782.62379 | I11: =IF(Loads!C27<>"", G11*$D$6/H11, "") -> 820.81583 | J11: =IF(Loads!C27<>"", 2*I11*(F11/H11)^2, "") -> 1313.3053 | K11: =IF(Loads!C27<>"", J11/J10, "") -> 0.94471896 | L11: =IF(Loads!C27<>"", IF(AND(K11>=0.8, K11<=1),"OK!","NG!"), "") -> OK!
C12: 5 | D12: =IF(Loads!C28<>"", 'Cross Sections and Materials'!C17, "") -> CHS 139.7x6.3 | E12: 350 | F12: 700 | G12: =IF(Loads!C28<>"", 'Cross Sections and Materials'!F17, "") -> 26.4 | H12: =IF(Loads!C28<>"", SQRT(E12^2+F12^2), "") -> 782.62379 | I12: =IF(Loads!C28<>"", G12*$D$6/H12, "") -> 708.38634 | J12: =IF(Loads!C28<>"", 2*I12*(F12/H12)^2, "") -> 1133.4181 | K12: =IF(Loads!C28<>"", J12/J11, "") -> 0.86302713 | L12: =IF(Loads!C28<>"", IF(AND(K12>=0.8, K12<=1),"OK!","NG!"), "") -> OK!
C13: 6 | D13: =IF(Loads!C29<>"", 'Cross Sections and Materials'!C18, "") -> CHS 177.8x6.3 | E13: 350 | F13: 700 | G13: =IF(Loads!C29<>"", 'Cross Sections and Materials'!F18, "") -> 32.38 | H13: =IF(Loads!C29<>"", SQRT(E13^2+F13^2), "") -> 782.62379 | I13: =IF(Loads!C29<>"", G13*$D$6/H13, "") -> 868.84657 | J13: =IF(Loads!C29<>"", 2*I13*(F13/H13)^2, "") -> 1390.1545 | K13: =IF(Loads!C29<>"", J13/J12, "") -> 1.2265152 | L13: =IF(Loads!C29<>"", IF(AND(K13>=0.8, K13<=1),"OK!","NG!"), "") -> NG!
C14: 7 | D14: =IF(Loads!C30<>"", 'Cross Sections and Materials'!C19, "") | G14: =IF(Loads!C30<>"", 'Cross Sections and Materials'!F19, "") | H14: =IF(Loads!C30<>"", SQRT(E14^2+F14^2), "") | I14: =IF(Loads!C30<>"", G14*$D$6/H14, "") | J14: =IF(Loads!C30<>"", 2*I14*(F14/H14)^2, "") | K14: =IF(Loads!C30<>"", J14/J13, "") | L14: =IF(Loads!C30<>"", IF(AND(K14>=0.8, K14<=1),"OK!","NG!"), "")
C15: 8 | D15: =IF(Loads!C31<>"", 'Cross Sections and Materials'!C20, "") | G15: =IF(Loads!C31<>"", 'Cross Sections and Materials'!F20, "") | H15: =IF(Loads!C31<>"", SQRT(E15^2+F15^2), "") | I15: =IF(Loads!C31<>"", G15*$D$6/H15, "") | J15: =IF(Loads!C31<>"", 2*I15*(F15/H15)^2, "") | K15: =IF(Loads!C31<>"", J15/J14, "") | L15: =IF(Loads!C31<>"", IF(AND(K15>=0.8, K15<=1),"OK!","NG!"), "")
C16: 9 | D16: =IF(Loads!C32<>"", 'Cross Sections and Materials'!C21, "") | G16: =IF(Loads!C32<>"", 'Cross Sections and Materials'!F21, "") | H16: =IF(Loads!C32<>"", SQRT(E16^2+F16^2), "") | I16: =IF(Loads!C32<>"", G16*$D$6/H16, "") | J16: =IF(Loads!C32<>"", 2*I16*(F16/H16)^2, "") | K16: =IF(Loads!C32<>"", J16/J15, "") | L16: =IF(Loads!C32<>"", IF(AND(K16>=0.8, K16<=1),"OK!","NG!"), "")
C18: EC8-1-2:2023 §4.4.4.2(1)b Structural regularity --> Mass
C20: Storey | D20: mi | E20: mi / mi-1
C21: 1 | D21: =IF(Loads!C24<>"", Loads!G40, "") -> 107.88991
C22: 2 | D22: =IF(Loads!C25<>"", Loads!G41, "") -> 107.88991 | E22: =IF(Loads!C25<>"", D22/D21, "") -> 1 | F22: =IF(Loads!C25<>"", IF(AND(E22>=0.8, E22<=1),"OK!","NG!"), "") -> OK! | G22: <-- must be constant or decrease by not more than 20%
C23: 3 | D23: =IF(Loads!C26<>"", Loads!G42, "") -> 107.88991 | E23: =IF(Loads!C26<>"", D23/D22, "") -> 1 | F23: =IF(Loads!C26<>"", IF(AND(E23>=0.8, E23<=1),"OK!","NG!"), "") -> OK!
C24: 4 | D24: =IF(Loads!C27<>"", Loads!G43, "") -> 107.88991 | E24: =IF(Loads!C27<>"", D24/D23, "") -> 1 | F24: =IF(Loads!C27<>"", IF(AND(E24>=0.8, E24<=1),"OK!","NG!"), "") -> OK!
C25: 5 | D25: =IF(Loads!C28<>"", Loads!G44, "") -> 107.88991 | E25: =IF(Loads!C28<>"", D25/D24, "") -> 1 | F25: =IF(Loads!C28<>"", IF(AND(E25>=0.8, E25<=1),"OK!","NG!"), "") -> OK!
C26: 6 | D26: =IF(Loads!C29<>"", Loads!G45, "") -> 96.330275 | E26: =IF(Loads!C29<>"", D26/D25, "") -> 0.89285714 | F26: =IF(Loads!C29<>"", IF(AND(E26>=0.8, E26<=1),"OK!","NG!"), "") -> OK!
C27: 7 | D27: =IF(Loads!C30<>"", Loads!G46, "") | E27: =IF(Loads!C30<>"", D27/D26, "") | F27: =IF(Loads!C30<>"", IF(AND(E27>=0.8, E27<=1),"OK!","NG!"), "")
C28: 8 | D28: =IF(Loads!C31<>"", Loads!G47, "") | E28: =IF(Loads!C31<>"", D28/D27, "") | F28: =IF(Loads!C31<>"", IF(AND(E28>=0.8, E28<=1),"OK!","NG!"), "")
C29: 9 | D29: =IF(Loads!C32<>"", Loads!G48, "") | E29: =IF(Loads!C32<>"", D29/D28, "") | F29: =IF(Loads!C32<>"", IF(AND(E29>=0.8, E29<=1),"OK!","NG!"), "")
C31: EC8-1-2:2023 §4.4.4(2)c Overstrength regularity
C33: Storey | D33: Section | E33: Storey N_Ed | F33: Act. Vtot | G33: Ω
C34: 1 | D34: =IF(Loads!C24<>"", D8, "") -> CHS 193.7x6 | E34: =IF(Loads!C24<>"", G108+(F108-E108), "") -> 677.2 | F34: =IF(Loads!C24<>"", I121+L108, "") -> 1237.7122 | G34: =IF(Loads!C24<>"", F34/E34, "") -> 1.8276908
C35: 2 | D35: =IF(Loads!C25<>"", D9, "") -> CHS 193.7x6 | E35: =IF(Loads!C25<>"", G109+(F109-E109), "") -> 591.4 | F35: =IF(Loads!C25<>"", I122+L109, "") -> 1237.7122 | G35: =IF(Loads!C25<>"", F35/E35, "") -> 2.0928512 | H35: =IF(Loads!C25<>"", G35/G34, "") -> 1.1450795 | I35: =IF(Loads!C25<>"", IF(AND(H35>=0.7, H35<=1.3),"OK!","NG!"), "") -> OK! | J35: <-- must not vary between storeys by more than 30%
C36: 3 | D36: =IF(Loads!C26<>"", D10, "") -> CHS 177.8x6.3 | E36: =IF(Loads!C26<>"", G110+(F110-E110), "") -> 544.2 | F36: =IF(Loads!C26<>"", I123+L110, "") -> 1097.1394 | G36: =IF(Loads!C26<>"", F36/E36, "") -> 2.0160592 | H36: =IF(Loads!C26<>"", G36/G35, "") -> 0.96330749 | I36: =IF(Loads!C26<>"", IF(AND(H36>=0.7, H36<=1.3),"OK!","NG!"), "") -> OK!
C37: 4 | D37: =IF(Loads!C27<>"", D11, "") -> CHS 168.3x6 | E37: =IF(Loads!C27<>"", G111+(F111-E111), "") -> 461.2 | F37: =IF(Loads!C27<>"", I124+L111, "") -> 1014.5742 | G37: =IF(Loads!C27<>"", F37/E37, "") -> 2.1998573 | H37: =IF(Loads!C27<>"", G37/G36, "") -> 1.091167 | I37: =IF(Loads!C27<>"", IF(AND(H37>=0.7, H37<=1.3),"OK!","NG!"), "") -> OK!
C38: 5 | D38: =IF(Loads!C28<>"", D12, "") -> CHS 139.7x6.3 | E38: =IF(Loads!C28<>"", G112+(F112-E112), "") -> 319 | F38: =IF(Loads!C28<>"", I125+L112, "") -> 814.73746 | G38: =IF(Loads!C28<>"", F38/E38, "") -> 2.5540359 | H38: =IF(Loads!C28<>"", G38/G37, "") -> 1.1610008 | I38: =IF(Loads!C28<>"", IF(AND(H38>=0.7, H38<=1.3),"OK!","NG!"), "") -> OK!
C39: 6 | D39: =IF(Loads!C29<>"", D13, "") -> CHS 177.8x6.3 | E39: =IF(Loads!C29<>"", G113+(F113-E113), "") -> 183.48 | F39: =IF(Loads!C29<>"", I126+L113, "") -> 1097.1394 | G39: =IF(Loads!C29<>"", F39/E39, "") -> 5.9796133 | H39: =IF(Loads!C29<>"", G39/G38, "") -> 2.3412409 | I39: =IF(Loads!C29<>"", IF(AND(H39>=0.7, H39<=1.3),"OK!","NG!"), "") -> NG!
C40: 7 | D40: =IF(Loads!C30<>"", D14, "") | E40: =IF(Loads!C30<>"", G114+(F114-E114), "") | F40: =IF(Loads!C30<>"", I127+L114, "") | G40: =IF(Loads!C30<>"", F40/E40, "") | H40: =IF(Loads!C30<>"", G40/G39, "") | I40: =IF(Loads!C30<>"", IF(AND(H40>=0.7, H40<=1.3),"OK!","NG!"), "")
C41: 8 | D41: =IF(Loads!C31<>"", D15, "") | E41: =IF(Loads!C31<>"", G115+(F115-E115), "") | F41: =IF(Loads!C31<>"", I128+L115, "") | G41: =IF(Loads!C31<>"", F41/E41, "") | H41: =IF(Loads!C31<>"", G41/G40, "") | I41: =IF(Loads!C31<>"", IF(AND(H41>=0.7, H41<=1.3),"OK!","NG!"), "")
C42: 9 | D42: =IF(Loads!C32<>"", D16, "") | E42: =IF(Loads!C32<>"", G116+(F116-E116), "") | F42: =IF(Loads!C32<>"", I129+L116, "") | G42: =IF(Loads!C32<>"", F42/E42, "") | H42: =IF(Loads!C32<>"", G42/G41, "") | I42: =IF(Loads!C32<>"", IF(AND(H42>=0.7, H42<=1.3),"OK!","NG!"), "")
C44: EC8-1-2:2023 §11.5(4) Storey Drifts: Control of second order effects
C45: qs_eff | D45: =MAX(Loads!C58,D119* 'Cross Sections and Materials'!Q9) -> 3.8217578
C46: Storey | D46: h [cm] | E46: ux,i [cm] | F46: ux,i-1 [cm] | G46: Δux,i [cm] | H46: dr [cm] | I46: Ptot [kN] | J46: Vtot [kN] | K46: θ
C47: 1 | D47: =IF(Loads!C24<>"", E8, "") -> 350 | E47: 0.4747 | F47: 0 | G47: =IF(Loads!C24<>"", E47-F47, "") -> 0.4747 | H47: =IF(Loads!C24<>"", G47*Loads!$C$60, "") -> 1.5038496 | I47: =IF(Loads!C24<>"", SUM(Loads!F40:$F$42), "") -> 3175.2 | J47: =IF(Loads!C24<>"", SUM(Loads!J40:$J$42), "") -> 170.9616 | K47: =IF(Loads!C24<>"", I47*H47/(Loads!$C$57*$D$45*CBF_Seismic_Design_Verification!J47*CBF_Seismic_Design_Verification!D47), "") -> 0.018982483 | L47: =IF(Loads!C24<>"", IF(K47<0.1,"OK!",IF(K47<0.2,"OK…","NG!")), "") -> OK!
...
